<?xml version="1.0" encoding="utf-8"?>
<!-- This URDF was automatically created by SolidWorks to URDF Exporter! Originally created by Stephen Brawner (brawner@gmail.com) 
     Commit Version: 1.6.0-4-g7f85cfe  Build Version: 1.6.7995.38578
     For more information, please see http://wiki.ros.org/sw_urdf_exporter -->
<robot
  name="simple_bot">

  <link name="base_link">
    <visual>
      <origin
        xyz="0 0 0.030"
        rpy="0 0 0" />
        <geometry>
            <cylinder
              radius="0.060"
              length="0.060" />
        </geometry>
    </visual>
  </link>
  <joint name="Joint1" type="revolute">
    <origin xyz="0 0 0.060" rpy="0 0 0" />
    <parent link="base_link" />
    <child link="Link1" />
    <axis xyz="0 0 1" />
    <limit lower="-3.14" upper="3.14" effort="100" velocity="3.14" />
  </joint>
  <link name="Link1">
    <visual>
      <origin
        xyz="0 0 0.080"
        rpy="0 1.57079632 0" />
        <geometry>
            <cylinder
              radius="0.060"
              length="0.060" />
        </geometry>
    </visual>
  </link>
  <joint name="Joint2" type="revolute">
    <origin xyz="0 0 0.08" rpy="0 0 0" />
    <parent link="Link1" />
    <child link="Link2" />
    <axis xyz="1 0 0" />
    <limit lower="-3.14" upper="3.14" effort="100" velocity="3.14" />
  </joint>
  <link name="Link2">
    <visual>
      <origin
        xyz="0 0.061 0.373"
        rpy="0 1.57079632 0" />
        <geometry>
            <cylinder
              radius="0.060"
              length="0.060" />
        </geometry>
    </visual>
  </link>
    <joint name="Joint3" type="revolute">
      <origin xyz="0 0.061 0.373" rpy="0 0 0" />
      <parent link="Link2" />
      <child link="Link3" />
      <axis xyz="1 0 0" />
      <limit lower="-3.14" upper="3.14" effort="100" velocity="3.14" />
    </joint>
    <link name="Link3">
      <visual>
        <origin
          xyz="0 0.1 0.050"
          rpy="1.57079632 0 0" />
        <geometry>
            <cylinder
              radius="0.0285"
              length="0.060" />
        </geometry>
      </visual>
    </link>
    <joint name="Joint4" type="revolute">
      <origin xyz="0 0.280 0.050" rpy="0 0 0" />
      <parent link="Link3" />
      <child link="Link4" />
      <axis xyz="0 1 0" />
      <limit lower="-3.14" upper="3.14" effort="100" velocity="3.14" />
    </joint>
    <link name="Link4">
      <visual>
        <origin
          xyz="0 0.0 0.0"
          rpy="0 1.57079632 0.0" />
        <geometry>
            <cylinder
              radius="0.0285"
              length="0.060" />
        </geometry>
      </visual>
    </link>
    <joint name="Joint5" type="revolute">
      <origin xyz="0 0.0 0.0" rpy="0 0 0" />
      <parent link="Link4" />
      <child link="Link5" />
      <axis xyz="1 0 0" />
      <limit lower="-3.14" upper="3.14" effort="100" velocity="3.14" />
    </joint>
    <link name="Link5">
        <visual>
          <origin
            xyz="0 0.1 0.0"
            rpy="1.57079632 0.0 0.0" />
          <geometry>
              <cylinder
                radius="0.0285"
                length="0.060" />
        </geometry>
      </visual>
    </link>
    <joint name="Joint6" type="revolute">
      <origin xyz="0 0.0 0.0" rpy="0 0 0" />
      <parent link="Link5" />
      <child link="Link6" />
      <axis xyz="0 1 0" />
      <limit lower="-3.14" upper="3.14" effort="100" velocity="3.14" />
    </joint>
    <link name="Link6">
        <visual>
          <origin
            xyz="0 0.15 0.0"
            rpy="1.57079632 0.0 0.0" />
          <geometry>
              <cylinder
                radius="0.03"
                length="0.01" />
              
        </geometry>
        <material name="">
          <color rgba="1 1 0 1" />
        </material>
      </visual>
    </link>
</robot>
